Workbook

Sheet Cover
A1: CASCADE OUTDOOR MANUFACTURING
A2: Corporate FP&A Budgeting & Forecasting Model
A4: Purpose
A5: Integrated financial planning model supporting budgeting, forecasting, scenario analysis, and management decision-making.
A7: Historical Period | B7: FY2023–FY2025
A8: Planning Period | B8: FY2026–FY2028
A10: Primary Tool | B10: Microsoft Excel for the Web
A11: Supporting Tool | B11: Power BI Desktop
A13: Model Status | B13: In Development
A15: Prepared for | B15: FP&A / Financial Business Intelligence Analysis

Sheet Control Panel
A1: Cascade Outdoor Manufacturing Control Panel
A3: Corporate FP&A Budgeting & Forecasting Model
A4: Company | B4: Cascade Outdoor Manufacturing
A5: Historical Start | B5: 44927
A6: Historical End | B6: 46022
A7: Forecast Start | B7: 46023
A8: Forecast End | B8: 47118
A10: Model QA Status | B10: ='Model QA'!D23 -> PASS
A11: Active Forecast Scenario | B11: ='Forecast Model'!B4 -> Base case
A12: Forecast Period | B12: 2026–2028
A13: 2028 Base Case Revenue | B13: ='Forecast Model'!E10 -> 6108131.1
A14: 2028 Base Case Operating Income | B14: ='Forecast Model'!E16 -> 1375445.1
A15: 2028 Base Case Free Cash Flow | B15: ='Cash Flow Plan'!E14 -> 1254249.1
A16: 2028 Ending Cash | B16: ='Cash Flow Plan'!E24 -> 4858967.8
A19: Management Forecast Summary
A21: Metric | B21: 2026 Forecast | C21: 2027 Forecast | D21: 2028 Forecast
A22: Revenue | B22: ='Forecast Model'!C10 -> 5247701.1 | C22: ='Forecast Model'!D10 -> 5661594 | D22: ='Forecast Model'!E10 -> 6108131.1
A23: Revenue Growth | B23: ='Forecast Model'!C11 -> 0.078871266 | C23: ='Forecast Model'!D11 -> 0.078871266 | D23: ='Forecast Model'!E11 -> 0.078871266
A24: Gross Profit | B24: ='Forecast Model'!C12 -> 2177796 | C24: ='Forecast Model'!D12 -> 2349561.5 | D24: ='Forecast Model'!E12 -> 2534874.4
A25: Gross Margin | B25: ='Forecast Model'!C13 -> 0.415 | C25: ='Forecast Model'!D13 -> 0.415 | D25: ='Forecast Model'!E13 -> 0.415
A26: Operating Expenses | B26: ='Forecast Model'!C14 -> -1051600.2 | C26: ='Forecast Model'!D14 -> -1104199.3 | D26: ='Forecast Model'!E14 -> -1159429.2
A27: Operating Income | B27: ='Forecast Model'!C16 -> 1126195.8 | C27: ='Forecast Model'!D16 -> 1245362.2 | D27: ='Forecast Model'!E16 -> 1375445.1
A28: Operating Margin | B28: ='Forecast Model'!C17 -> 0.21460745 | C28: ='Forecast Model'!D17 -> 0.21996671 | D28: ='Forecast Model'!E17 -> 0.22518265
A29: Net Income | B29: ='Forecast Model'!C18 -> 969654.55 | C29: ='Forecast Model'!D18 -> 1072256.9 | D29: ='Forecast Model'!E18 -> 1184258.3
A30: Free Cash Flow | B30: ='Cash Flow Plan'!C14 -> 863795.76 | C30: ='Cash Flow Plan'!D14 -> 1051842.2 | D30: ='Cash Flow Plan'!E14 -> 1254249.1
A31: Ending Cash | B31: ='Cash Flow Plan'!C24 -> 2552876.5 | C31: ='Cash Flow Plan'!D24 -> 3604718.7 | D31: ='Cash Flow Plan'!E24 -> 4858967.8
A32: Total Headcount | B32: ='Headcount Plan'!C12 -> 97 | C32: ='Headcount Plan'!D12 -> 102 | D32: ='Headcount Plan'!E12 -> 107
A33: Employment Cost | B33: ='Headcount Plan'!C71 -> 6171580.8 | C33: ='Headcount Plan'!D71 -> 6721122.7 | D33: ='Headcount Plan'!E71 -> 7301572.4
A34: Capital Expenditures | B34: ='CapEx Plan'!C12 -> 430500 | C34: ='CapEx Plan'!D12 -> 452025 | D34: ='CapEx Plan'!E12 -> 474626.25
A36: Three-Year Revenue CAGR | B36: =('Forecast Model'!E10/'Forecast Model'!B10)^(1/3)-1 -> 0.078871266
A37: Operating Margin Change | B37: ='Forecast Model'!E17-'Forecast Model'!B17 -> 0.01608173
A38: 2026–2028 Free Cash Flow Growth | B38: =('Cash Flow Plan'!E14/'Cash Flow Plan'!C14)^(1/2)-1 -> 0.20499813
A39: Management Reporting Status | B39: =IF(AND(B10="PASS",B11="Base case"),"READY","REVIEW") -> READY
A42: Forecast Driver Analysis
A44: Metric | B44: 2026 | C44: 2027 | D44: 2028 | E44: 2026–2028 Change
A45: Revenue | B45: ='Forecast Model'!C10 -> 5247701.1 | C45: ='Forecast Model'!D10 -> 5661594 | D45: ='Forecast Model'!E10 -> 6108131.1 | E45: =D45-B45 -> 860429.92
A46: Revenue Growth | B46: ='Forecast Model'!C11 -> 0.078871266 | C46: ='Forecast Model'!D11 -> 0.078871266 | D46: ='Forecast Model'!E11 -> 0.078871266 | E46: =D46-B46 -> 0
A47: Gross Margin | B47: ='Forecast Model'!C13 -> 0.415 | C47: ='Forecast Model'!D13 -> 0.415 | D47: ='Forecast Model'!E13 -> 0.415 | E47: =D47-B47 -> 0
A48: Operating Expenses | B48: ='Forecast Model'!C14 -> -1051600.2 | C48: ='Forecast Model'!D14 -> -1104199.3 | D48: ='Forecast Model'!E14 -> -1159429.2 | E48: =D48-B48 -> -107829.03
A49: Operating Income | B49: ='Forecast Model'!C16 -> 1126195.8 | C49: ='Forecast Model'!D16 -> 1245362.2 | D49: ='Forecast Model'!E16 -> 1375445.1 | E49: =D49-B49 -> 249249.38
...

Sheet Accounts
A1: AccountKey | B1: AccountNumber | C1: AccountName | D1: FinancialStatement | E1: AccountCategory | F1: NormalBalance
A2: 1 | B2: 1000 | C2: Cash | D2: Balance Sheet | E2: Asset | F2: Debit
A3: 2 | B3: 1100 | C3: Accounts Receivable | D3: Balance Sheet | E3: Asset | F3: Debit
A4: 3 | B4: 1200 | C4: Inventory | D4: Balance Sheet | E4: Asset | F4: Debit
A5: 4 | B5: 1300 | C5: Prepaid Expenses | D5: Balance Sheet | E5: Asset | F5: Debit
A6: 5 | B6: 1500 | C6: Equipment | D6: Balance Sheet | E6: Asset | F6: Debit
A7: 6 | B7: 2000 | C7: Accounts Payable | D7: Balance Sheet | E7: Liability | F7: Credit
A8: 7 | B8: 2100 | C8: Accrued Expenses | D8: Balance Sheet | E8: Liability | F8: Credit
A9: 8 | B9: 2200 | C9: Long-Term Debt | D9: Balance Sheet | E9: Liability | F9: Credit
A10: 9 | B10: 3000 | C10: Retained Earnings | D10: Balance Sheet | E10: Equity | F10: Credit
A11: 10 | B11: 3100 | C11: Common Stock | D11: Balance Sheet | E11: Equity | F11: Credit
A12: 11 | B12: 4000 | C12: Product Revenue | D12: Income Statement | E12: Revenue | F12: Credit
A13: 12 | B13: 4010 | C13: Service Revenue | D13: Income Statement | E13: Revenue | F13: Credit
... A26: 25 | B26: 8200 | C26: Income Tax Expense | D26: Income Statement | E26: Tax Expense | F26: Debit

Sheet Business Units
A1: BusinessUnitKey | B1: BusinessUnitID | C1: BusinessUnitName
A2: 1 | B2: BUO1 | C2: Manufacturing
A3: 2 | B3: BUO2 | C3: Wholesale
A4: 3 | B4: BUO3 | C4: Retail
A5: 4 | B5: BUO4 | C5: E-Commerce

Sheet Calendar
A1: DateKey | B1: FullDate | C1: CalendarYear | D1: CalendarQuarter | E1: MonthNumber | F1: MonthName | G1: MonthYear | H1: FiscalYear
A2: 20230101 | B2: 44927 | C2: 2023 | D2: 1 | E2: 1 | F2: January | G2: Jan 2023 | H2: FY2023
A3: 20230102 | B3: 44928 | C3: 2023 | D3: 1 | E3: 1 | F3: January | G3: Jan 2023 | H3: FY2023
A4: 20230103 | B4: 44929 | C4: 2023 | D4: 1 | E4: 1 | F4: January | G4: Jan 2023 | H4: FY2023
A5: 20230104 | B5: 44930 | C5: 2023 | D5: 1 | E5: 1 | F5: January | G5: Jan 2023 | H5: FY2023
A6: 20230105 | B6: 44931 | C6: 2023 | D6: 1 | E6: 1 | F6: January | G6: Jan 2023 | H6: FY2023
A7: 20230106 | B7: 44932 | C7: 2023 | D7: 1 | E7: 1 | F7: January | G7: Jan 2023 | H7: FY2023
A8: 20230107 | B8: 44933 | C8: 2023 | D8: 1 | E8: 1 | F8: January | G8: Jan 2023 | H8: FY2023
A9: 20230108 | B9: 44934 | C9: 2023 | D9: 1 | E9: 1 | F9: January | G9: Jan 2023 | H9: FY2023
A10: 20230109 | B10: 44935 | C10: 2023 | D10: 1 | E10: 1 | F10: January | G10: Jan 2023 | H10: FY2023
A11: 20230110 | B11: 44936 | C11: 2023 | D11: 1 | E11: 1 | F11: January | G11: Jan 2023 | H11: FY2023
A12: 20230111 | B12: 44937 | C12: 2023 | D12: 1 | E12: 1 | F12: January | G12: Jan 2023 | H12: FY2023
A13: 20230112 | B13: 44938 | C13: 2023 | D13: 1 | E13: 1 | F13: January | G13: Jan 2023 | H13: FY2023
... A1097: 20251231 | B1097: 46022 | C1097: 2025 | D1097: 4 | E1097: 12 | F1097: December | G1097: Dec 2025 | H1097: FY2025

Sheet Departments
A1: DepartmentKey | B1: DepartmentID | C1: DepartmentName
A2: 1 | B2: D001 | C2: Executive
A3: 2 | B3: D002 | C3: Finance
A4: 3 | B4: D003 | C4: Human Resources
A5: 4 | B5: D004 | C5: Sales
A6: 5 | B6: D005 | C6: Marketing
A7: 6 | B7: D006 | C7: Operations
A8: 7 | B8: D007 | C8: Information Technology
A9: 8 | B9: D008 | C9: Customer Service

Sheet Financial Statements
A1: DateKey | B1: DepartmentKey | C1: BusinessUnitKey | D1: RegionKey | E1: AccountKey | F1: Scenario | G1: Amount | H1: FullDate | I1: AccountNumber | J1: AccountName | K1: FinancialStatement | L1: AccountCategory | M1: NormalBalance | N1: DepartmentName | O1: BusinessUnitName | P1: RegionName
A2: 20230101 | B2: 3 | C2: 1 | D2: 4 | E2: 13 | F2: Actual | G2: 24822.25 | H2: =_xlfn.XLOOKUP(tblFinancials[[#This Row],[DateKey]],tblCalendar[DateKey],tblCalendar[FullDate],"") -> 44927 | I2: =_xlfn.XLOOKUP(tblFinancials[[#This Row],[AccountKey]],tblAccounts[AccountKey],tblAccounts[AccountNumber],"") -> 4020 | J2: =_xlfn.XLOOKUP(tblFinancials[[#This Row],[AccountKey]],tblAccounts[AccountKey],tblAccounts[AccountName],"") -> Online Revenue | K2: =_xlfn.XLOOKUP(tblFinancials[[#This Row],[AccountKey]],tblAccounts[AccountKey],tblAccounts[FinancialStatement],"") -> Income Statement | L2: =_xlfn.XLOOKUP(tblFinancials[[#This Row],[AccountKey]],tblAccounts[AccountKey],tblAccounts[AccountCategory],"") -> Revenue | M2: =_xlfn.XLOOKUP(tblFinancials[[#This Row],[AccountKey]],tblAccounts[AccountKey],tblAccounts[NormalBalance],"") -> Credit | N2: =_xlfn.XLOOKUP(tblFinancials[[#This Row],[DepartmentKey]],tblDepartments[DepartmentKey],tblDepartments[DepartmentName],"") -> Human Resources | O2: =_xlfn.XLOOKUP(tblFinancials[[#This Row],[BusinessUnitKey]],tblBusinessUnits[BusinessUnitKey],tblBusinessUnits[BusinessUnitName],"") -> Manufacturing | P2: =_xlfn.XLOOKUP(tblFinancials[[#This Row],[RegionKey]],tblRegions[RegionKey],tblRegions[RegionName],"") -> East
A3: 20230101 | B3: 2 | C3: 1 | D3: 2 | E3: 13 | F3: Actual | G3: 24542.67 | H3: =_xlfn.XLOOKUP(tblFinancials[[#This Row],[DateKey]],tblCalendar[DateKey],tblCalendar[FullDate],"") -> 44927 | I3: =_xlfn.XLOOKUP(tblFinancials[[#This Row],[AccountKey]],tblAccounts[AccountKey],tblAccounts[AccountNumber],"") -> 4020 | J3: =_xlfn.XLOOKUP(tblFinancials[[#This Row],[AccountKey]],tblAccounts[AccountKey],tblAccounts[AccountName],"") -> Online Revenue | K3: =_xlfn.XLOOKUP(tblFinancials[[#This Row],[AccountKey]],tblAccounts[AccountKey],tblAccounts[FinancialStatement],"") -> Income Statement | L3: =_xlfn.XLOOKUP(tblFinancials[[#This Row],[AccountKey]],tblAccounts[AccountKey],tblAccounts[AccountCategory],"") -> Revenue | M3: =_xlfn.XLOOKUP(tblFinancials[[#This Row],[AccountKey]],tblAccounts[AccountKey],tblAccounts[NormalBalance],"") -> Credit | N3: =_xlfn.XLOOKUP(tblFinancials[[#This Row],[DepartmentKey]],tblDepartments[DepartmentKey],tblDepartments[DepartmentName],"") -> Finance | O3: =_xlfn.XLOOKUP(tblFinancials[[#This Row],[BusinessUnitKey]],tblBusinessUnits[BusinessUnitKey],tblBusinessUnits[BusinessUnitName],"") -> Manufacturing | P3: =_xlfn.XLOOKUP(tblFinancials[[#This Row],[RegionKey]],tblRegions[RegionKey],tblRegions[RegionName],"") -> Midwest
A4: 20230101 | B4: 4 | C4: 1 | D4: 1 | E4: 13 | F4: Actual | G4: 25107.18 | H4: =_xlfn.XLOOKUP(tblFinancials[[#This Row],[DateKey]],tblCalendar[DateKey],tblCalendar[FullDate],"") -> 44927 | I4: =_xlfn.XLOOKUP(tblFinancials[[#This Row],[AccountKey]],tblAccounts[AccountKey],tblAccounts[AccountNumber],"") -> 4020 | J4: =_xlfn.XLOOKUP(tblFinancials[[#This Row],[AccountKey]],tblAccounts[AccountKey],tblAccounts[AccountName],"") -> Online Revenue | K4: =_xlfn.XLOOKUP(tblFinancials[[#This Row],[AccountKey]],tblAccounts[AccountKey],tblAccounts[FinancialStatement],"") -> Income Statement | L4: =_xlfn.XLOOKUP(tblFinancials[[#This Row],[AccountKey]],tblAccounts[AccountKey],tblAccounts[AccountCategory],"") -> Revenue | M4: =_xlfn.XLOOKUP(tblFinancials[[#This Row],[AccountKey]],tblAccounts[AccountKey],tblAccounts[NormalBalance],"") -> Credit | N4: =_xlfn.XLOOKUP(tblFinancials[[#This Row],[DepartmentKey]],tblDepartments[DepartmentKey],tblDepartments[DepartmentName],"") -> Sales | O4: =_xlfn.XLOOKUP(tblFinancials[[#This Row],[BusinessUnitKey]],tblBusinessUnits[BusinessUnitKey],tblBusinessUnits[BusinessUnitName],"") -> Manufacturing | P4: =_xlfn.XLOOKUP(tblFinancials[[#This Row],[RegionKey]],tblRegions[RegionKey],tblRegions[RegionName],"") -> West
A5: 20230101 | B5: 3 | C5: 1 | D5: 1 | E5: 12 | F5: Actual | G5: 24660.76 | H5: =_xlfn.XLOOKUP(tblFinancials[[#This Row],[DateKey]],tblCalendar[DateKey],tblCalendar[FullDate],"") -> 44927 | I5: =_xlfn.XLOOKUP(tblFinancials[[#This Row],[AccountKey]],tblAccounts[AccountKey],tblAccounts[AccountNumber],"") -> 4010 | J5: =_xlfn.XLOOKUP(tblFinancials[[#This Row],[AccountKey]],tblAccounts[AccountKey],tblAccounts[AccountName],"") -> Service Revenue | K5: =_xlfn.XLOOKUP(tblFinancials[[#This Row],[AccountKey]],tblAccounts[AccountKey],tblAccounts[FinancialStatement],"") -> Income Statement | L5: =_xlfn.XLOOKUP(tblFinancials[[#This Row],[AccountKey]],tblAccounts[AccountKey],tblAccounts[AccountCategory],"") -> Revenue | M5: =_xlfn.XLOOKUP(tblFinancials[[#This Row],[AccountKey]],tblAccounts[AccountKey],tblAccounts[NormalBalance],"") -> Credit | N5: =_xlfn.XLOOKUP(tblFinancials[[#This Row],[DepartmentKey]],tblDepartments[DepartmentKey],tblDepartments[DepartmentName],"") -> Human Resources | O5: =_xlfn.XLOOKUP(tblFinancials[[#This Row],[BusinessUnitKey]],tblBusinessUnits[BusinessUnitKey],tblBusinessUnits[BusinessUnitName],"") -> Manufacturing | P5: =_xlfn.XLOOKUP(tblFinancials[[#This Row],[RegionKey]],tblRegions[RegionKey],tblRegions[RegionName],"") -> West
A6: 20230101 | B6: 8 | C6: 3 | D6: 1 | E6: 11 | F6: Actual | G6: 25016.45 | H6: =_xlfn.XLOOKUP(tblFinancials[[#This Row],[DateKey]],tblCalendar[DateKey],tblCalendar[FullDate],"") -> 44927 | I6: =_xlfn.XLOOKUP(tblFinancials[[#This Row],[AccountKey]],tblAccounts[AccountKey],tblAccounts[AccountNumber],"") -> 4000 | J6: =_xlfn.XLOOKUP(tblFinancials[[#This Row],[AccountKey]],tblAccounts[AccountKey],tblAccounts[AccountName],"") -> Product Revenue | K6: =_xlfn.XLOOKUP(tblFinancials[[#This Row],[AccountKey]],tblAccounts[AccountKey],tblAccounts[FinancialStatement],"") -> Income Statement | L6: =_xlfn.XLOOKUP(tblFinancials[[#This Row],[AccountKey]],tblAccounts[AccountKey],tblAccounts[AccountCategory],"") -> Revenue | M6: =_xlfn.XLOOKUP(tblFinancials[[#This Row],[AccountKey]],tblAccounts[AccountKey],tblAccounts[NormalBalance],"") -> Credit | N6: =_xlfn.XLOOKUP(tblFinancials[[#This Row],[DepartmentKey]],tblDepartments[DepartmentKey],tblDepartments[DepartmentName],"") -> Customer Service | O6: =_xlfn.XLOOKUP(tblFinancials[[#This Row],[BusinessUnitKey]],tblBusinessUnits[BusinessUnitKey],tblBusinessUnits[BusinessUnitName],"") -> Retail | P6: =_xlfn.XLOOKUP(tblFinancials[[#This Row],[RegionKey]],tblRegions[RegionKey],tblRegions[RegionName],"") -> West
A7: 20230101 | B7: 3 | C7: 3 | D7: 2 | E7: 13 | F7: Actual | G7: 25695.69 | H7: =_xlfn.XLOOKUP(tblFinancials[[#This Row],[DateKey]],tblCalendar[DateKey],tblCalendar[FullDate],"") -> 44927 | I7: =_xlfn.XLOOKUP(tblFinancials[[#This Row],[AccountKey]],tblAccounts[AccountKey],tblAccounts[AccountNumber],"") -> 4020 | J7: =_xlfn.XLOOKUP(tblFinancials[[#This Row],[AccountKey]],tblAccounts[AccountKey],tblAccounts[AccountName],"") -> Online Revenue | K7: =_xlfn.XLOOKUP(tblFinancials[[#This Row],[AccountKey]],tblAccounts[AccountKey],tblAccounts[FinancialStatement],"") -> Income Statement | L7: =_xlfn.XLOOKUP(tblFinancials[[#This Row],[AccountKey]],tblAccounts[AccountKey],tblAccounts[AccountCategory],"") -> Revenue | M7: =_xlfn.XLOOKUP(tblFinancials[[#This Row],[AccountKey]],tblAccounts[AccountKey],tblAccounts[NormalBalance],"") -> Credit | N7: =_xlfn.XLOOKUP(tblFinancials[[#This Row],[DepartmentKey]],tblDepartments[DepartmentKey],tblDepartments[DepartmentName],"") -> Human Resources | O7: =_xlfn.XLOOKUP(tblFinancials[[#This Row],[BusinessUnitKey]],tblBusinessUnits[BusinessUnitKey],tblBusinessUnits[BusinessUnitName],"") -> Retail | P7: =_xlfn.XLOOKUP(tblFinancials[[#This Row],[RegionKey]],tblRegions[RegionKey],tblRegions[RegionName],"") -> Midwest
A8: 20230101 | B8: 5 | C8: 2 | D8: 4 | E8: 13 | F8: Actual | G8: 26476.68 | H8: =_xlfn.XLOOKUP(tblFinancials[[#This Row],[DateKey]],tblCalendar[DateKey],tblCalendar[FullDate],"") -> 44927 | I8: =_xlfn.XLOOKUP(tblFinancials[[#This Row],[AccountKey]],tblAccounts[AccountKey],tblAccounts[AccountNumber],"") -> 4020 | J8: =_xlfn.XLOOKUP(tblFinancials[[#This Row],[AccountKey]],tblAccounts[AccountKey],tblAccounts[AccountName],"") -> Online Revenue | K8: =_xlfn.XLOOKUP(tblFinancials[[#This Row],[AccountKey]],tblAccounts[AccountKey],tblAccounts[FinancialStatement],"") -> Income Statement | L8: =_xlfn.XLOOKUP(tblFinancials[[#This Row],[AccountKey]],tblAccounts[AccountKey],tblAccounts[AccountCategory],"") -> Revenue | M8: =_xlfn.XLOOKUP(tblFinancials[[#This Row],[AccountKey]],tblAccounts[AccountKey],tblAccounts[NormalBalance],"") -> Credit | N8: =_xlfn.XLOOKUP(tblFinancials[[#This Row],[DepartmentKey]],tblDepartments[DepartmentKey],tblDepartments[DepartmentName],"") -> Marketing | O8: =_xlfn.XLOOKUP(tblFinancials[[#This Row],[BusinessUnitKey]],tblBusinessUnits[BusinessUnitKey],tblBusinessUnits[BusinessUnitName],"") -> Wholesale | P8: =_xlfn.XLOOKUP(tblFinancials[[#This Row],[RegionKey]],tblRegions[RegionKey],tblRegions[RegionName],"") -> East
A9: 20230101 | B9: 6 | C9: 4 | D9: 3 | E9: 11 | F9: Actual | G9: 24155.29 | H9: =_xlfn.XLOOKUP(tblFinancials[[#This Row],[DateKey]],tblCalendar[DateKey],tblCalendar[FullDate],"") -> 44927 | I9: =_xlfn.XLOOKUP(tblFinancials[[#This Row],[AccountKey]],tblAccounts[AccountKey],tblAccounts[AccountNumber],"") -> 4000 | J9: =_xlfn.XLOOKUP(tblFinancials[[#This Row],[AccountKey]],tblAccounts[AccountKey],tblAccounts[AccountName],"") -> Product Revenue | K9: =_xlfn.XLOOKUP(tblFinancials[[#This Row],[AccountKey]],tblAccounts[AccountKey],tblAccounts[FinancialStatement],"") -> Income Statement | L9: =_xlfn.XLOOKUP(tblFinancials[[#This Row],[AccountKey]],tblAccounts[AccountKey],tblAccounts[AccountCategory],"") -> Revenue | M9: =_xlfn.XLOOKUP(tblFinancials[[#This Row],[AccountKey]],tblAccounts[AccountKey],tblAccounts[NormalBalance],"") -> Credit | N9: =_xlfn.XLOOKUP(tblFinancials[[#This Row],[DepartmentKey]],tblDepartments[DepartmentKey],tblDepartments[DepartmentName],"") -> Operations | O9: =_xlfn.XLOOKUP(tblFinancials[[#This Row],[BusinessUnitKey]],tblBusinessUnits[BusinessUnitKey],tblBusinessUnits[BusinessUnitName],"") -> E-Commerce | P9: =_xlfn.XLOOKUP(tblFinancials[[#This Row],[RegionKey]],tblRegions[RegionKey],tblRegions[RegionName],"") -> South
A10: 20230101 | B10: 7 | C10: 3 | D10: 2 | E10: 11 | F10: Actual | G10: 24350.19 | H10: =_xlfn.XLOOKUP(tblFinancials[[#This Row],[DateKey]],tblCalendar[DateKey],tblCalendar[FullDate],"") -> 44927 | I10: =_xlfn.XLOOKUP(tblFinancials[[#This Row],[AccountKey]],tblAccounts[AccountKey],tblAccounts[AccountNumber],"") -> 4000 | J10: =_xlfn.XLOOKUP(tblFinancials[[#This Row],[AccountKey]],tblAccounts[AccountKey],tblAccounts[AccountName],"") -> Product Revenue | K10: =_xlfn.XLOOKUP(tblFinancials[[#This Row],[AccountKey]],tblAccounts[AccountKey],tblAccounts[FinancialStatement],"") -> Income Statement | L10: =_xlfn.XLOOKUP(tblFinancials[[#This Row],[AccountKey]],tblAccounts[AccountKey],tblAccounts[AccountCategory],"") -> Revenue | M10: =_xlfn.XLOOKUP(tblFinancials[[#This Row],[AccountKey]],tblAccounts[AccountKey],tblAccounts[NormalBalance],"") -> Credit | N10: =_xlfn.XLOOKUP(tblFinancials[[#This Row],[DepartmentKey]],tblDepartments[DepartmentKey],tblDepartments[DepartmentName],"") -> Information Technology | O10: =_xlfn.XLOOKUP(tblFinancials[[#This Row],[BusinessUnitKey]],tblBusinessUnits[BusinessUnitKey],tblBusinessUnits[BusinessUnitName],"") -> Retail | P10: =_xlfn.XLOOKUP(tblFinancials[[#This Row],[RegionKey]],tblRegions[RegionKey],tblRegions[RegionName],"") -> Midwest
A11: 20230101 | B11: 2 | C11: 4 | D11: 2 | E11: 11 | F11: Actual | G11: 26247.62 | H11: =_xlfn.XLOOKUP(tblFinancials[[#This Row],[DateKey]],tblCalendar[DateKey],tblCalendar[FullDate],"") -> 44927 | I11: =_xlfn.XLOOKUP(tblFinancials[[#This Row],[AccountKey]],tblAccounts[AccountKey],tblAccounts[AccountNumber],"") -> 4000 | J11: =_xlfn.XLOOKUP(tblFinancials[[#This Row],[AccountKey]],tblAccounts[AccountKey],tblAccounts[AccountName],"") -> Product Revenue | K11: =_xlfn.XLOOKUP(tblFinancials[[#This Row],[AccountKey]],tblAccounts[AccountKey],tblAccounts[FinancialStatement],"") -> Income Statement | L11: =_xlfn.XLOOKUP(tblFinancials[[#This Row],[AccountKey]],tblAccounts[AccountKey],tblAccounts[AccountCategory],"") -> Revenue | M11: =_xlfn.XLOOKUP(tblFinancials[[#This Row],[AccountKey]],tblAccounts[AccountKey],tblAccounts[NormalBalance],"") -> Credit | N11: =_xlfn.XLOOKUP(tblFinancials[[#This Row],[DepartmentKey]],tblDepartments[DepartmentKey],tblDepartments[DepartmentName],"") -> Finance | O11: =_xlfn.XLOOKUP(tblFinancials[[#This Row],[BusinessUnitKey]],tblBusinessUnits[BusinessUnitKey],tblBusinessUnits[BusinessUnitName],"") -> E-Commerce | P11: =_xlfn.XLOOKUP(tblFinancials[[#This Row],[RegionKey]],tblRegions[RegionKey],tblRegions[RegionName],"") -> Midwest
A12: 20230101 | B12: 6 | C12: 2 | D12: 2 | E12: 11 | F12: Actual | G12: 25929.8 | H12: =_xlfn.XLOOKUP(tblFinancials[[#This Row],[DateKey]],tblCalendar[DateKey],tblCalendar[FullDate],"") -> 44927 | I12: =_xlfn.XLOOKUP(tblFinancials[[#This Row],[AccountKey]],tblAccounts[AccountKey],tblAccounts[AccountNumber],"") -> 4000 | J12: =_xlfn.XLOOKUP(tblFinancials[[#This Row],[AccountKey]],tblAccounts[AccountKey],tblAccounts[AccountName],"") -> Product Revenue | K12: =_xlfn.XLOOKUP(tblFinancials[[#This Row],[AccountKey]],tblAccounts[AccountKey],tblAccounts[FinancialStatement],"") -> Income Statement | L12: =_xlfn.XLOOKUP(tblFinancials[[#This Row],[AccountKey]],tblAccounts[AccountKey],tblAccounts[AccountCategory],"") -> Revenue | M12: =_xlfn.XLOOKUP(tblFinancials[[#This Row],[AccountKey]],tblAccounts[AccountKey],tblAccounts[NormalBalance],"") -> Credit | N12: =_xlfn.XLOOKUP(tblFinancials[[#This Row],[DepartmentKey]],tblDepartments[DepartmentKey],tblDepartments[DepartmentName],"") -> Operations | O12: =_xlfn.XLOOKUP(tblFinancials[[#This Row],[BusinessUnitKey]],tblBusinessUnits[BusinessUnitKey],tblBusinessUnits[BusinessUnitName],"") -> Wholesale | P12: =_xlfn.XLOOKUP(tblFinancials[[#This Row],[RegionKey]],tblRegions[RegionKey],tblRegions[RegionName],"") -> Midwest
A13: 20230101 | B13: 2 | C13: 4 | D13: 1 | E13: 13 | F13: Actual | G13: 27088.81 | H13: =_xlfn.XLOOKUP(tblFinancials[[#This Row],[DateKey]],tblCalendar[DateKey],tblCalendar[FullDate],"") -> 44927 | I13: =_xlfn.XLOOKUP(tblFinancials[[#This Row],[AccountKey]],tblAccounts[AccountKey],tblAccounts[AccountNumber],"") -> 4020 | J13: =_xlfn.XLOOKUP(tblFinancials[[#This Row],[AccountKey]],tblAccounts[AccountKey],tblAccounts[AccountName],"") -> Online Revenue | K13: =_xlfn.XLOOKUP(tblFinancials[[#This Row],[AccountKey]],tblAccounts[AccountKey],tblAccounts[FinancialStatement],"") -> Income Statement | L13: =_xlfn.XLOOKUP(tblFinancials[[#This Row],[AccountKey]],tblAccounts[AccountKey],tblAccounts[AccountCategory],"") -> Revenue | M13: =_xlfn.XLOOKUP(tblFinancials[[#This Row],[AccountKey]],tblAccounts[AccountKey],tblAccounts[NormalBalance],"") -> Credit | N13: =_xlfn.XLOOKUP(tblFinancials[[#This Row],[DepartmentKey]],tblDepartments[DepartmentKey],tblDepartments[DepartmentName],"") -> Finance | O13: =_xlfn.XLOOKUP(tblFinancials[[#This Row],[BusinessUnitKey]],tblBusinessUnits[BusinessUnitKey],tblBusinessUnits[BusinessUnitName],"") -> E-Commerce | P13: =_xlfn.XLOOKUP(tblFinancials[[#This Row],[RegionKey]],tblRegions[RegionKey],tblRegions[RegionName],"") -> West
... A1297: 20251201 | B1297: 5 | C1297: 4 | D1297: 2 | E1297: 21 | F1297: Actual | G1297: -6874.77 | H1297: =_xlfn.XLOOKUP(tblFinancials[[#This Row],[DateKey]],tblCalendar[DateKey],tblCalendar[FullDate],"") -> 45992 | I1297: =_xlfn.XLOOKUP(tblFinancials[[#This Row],[AccountKey]],tblAccounts[AccountKey],tblAccounts[AccountNumber],"") -> 6600 | J1297: =_xlfn.XLOOKUP(tblFinancials[[#This Row],[AccountKey]],tblAccounts[AccountKey],tblAccounts[AccountName],"") -> Utilities Expense | K1297: =_xlfn.XLOOKUP(tblFinancials[[#This Row],[AccountKey]],tblAccounts[AccountKey],tblAccounts[FinancialStatement],"") -> Income Statement | L1297: =_xlfn.XLOOKUP(tblFinancials[[#This Row],[AccountKey]],tblAccounts[AccountKey],tblAccounts[AccountCategory],"") -> Operating Expense | M1297: =_xlfn.XLOOKUP(tblFinancials[[#This Row],[AccountKey]],tblAccounts[AccountKey],tblAccounts[NormalBalance],"") -> Debit | N1297: =_xlfn.XLOOKUP(tblFinancials[[#This Row],[DepartmentKey]],tblDepartments[DepartmentKey],tblDepartments[DepartmentName],"") -> Marketing | O1297: =_xlfn.XLOOKUP(tblFinancials[[#This Row],[BusinessUnitKey]],tblBusinessUnits[BusinessUnitKey],tblBusinessUnits[BusinessUnitName],"") -> E-Commerce | P1297: =_xlfn.XLOOKUP(tblFinancials[[#This Row],[RegionKey]],tblRegions[RegionKey],tblRegions[RegionName],"") -> Midwest

Sheet Regions
A1: RegionKey | B1: RegionID | C1: RegionName
A2: 1 | B2: R01 | C2: West
A3: 2 | B3: R02 | C3: Midwest
A4: 3 | B4: R03 | C4: South
A5: 4 | B5: R04 | C5: East

Sheet Historical Actuals
A1: CASCADE OUTDOOR MANUFACTURING
A2: Historical Income Statement
A4: Account | B4: 2023 | C4: 2024 | D4: 2025 | E4: 2024 YoY % | F4: 2025 YoY %
A5: Revenue
A6: Product Revenue | B6: =SUMIFS(tblFinancials[Amount],tblFinancials[AccountName],$A6,tblFinancials[FullDate],">="&DATE(B$4,1,1),tblFinancials[FullDate],"<="&DATE(B$4,12,31)) -> 1358696.8 | C6: =SUMIFS(tblFinancials[Amount],tblFinancials[AccountName],$A6,tblFinancials[FullDate],">="&DATE(C$4,1,1),tblFinancials[FullDate],"<="&DATE(C$4,12,31)) -> 1542816.8 | D6: =SUMIFS(tblFinancials[Amount],tblFinancials[AccountName],$A6,tblFinancials[FullDate],">="&DATE(D$4,1,1),tblFinancials[FullDate],"<="&DATE(D$4,12,31)) -> 1593911.6 | E6: =IFERROR(C6/B6-1,0) -> 0.13551221 | F6: =IFERROR(D6/C6-1,0) -> 0.033117892
A7: Service Revenue | B7: =SUMIFS(tblFinancials[Amount],tblFinancials[AccountName],$A7,tblFinancials[FullDate],">="&DATE(B$4,1,1),tblFinancials[FullDate],"<="&DATE(B$4,12,31)) -> 1487698.5 | C7: =SUMIFS(tblFinancials[Amount],tblFinancials[AccountName],$A7,tblFinancials[FullDate],">="&DATE(C$4,1,1),tblFinancials[FullDate],"<="&DATE(C$4,12,31)) -> 1468097.8 | D7: =SUMIFS(tblFinancials[Amount],tblFinancials[AccountName],$A7,tblFinancials[FullDate],">="&DATE(D$4,1,1),tblFinancials[FullDate],"<="&DATE(D$4,12,31)) -> 2075959.7 | E7: =IFERROR(C7/B7-1,0) -> -0.013175169 | F7: =IFERROR(D7/C7-1,0) -> 0.41404724
A8: Online Revenue | B8: =SUMIFS(tblFinancials[Amount],tblFinancials[AccountName],$A8,tblFinancials[FullDate],">="&DATE(B$4,1,1),tblFinancials[FullDate],"<="&DATE(B$4,12,31)) -> 1332487.7 | C8: =SUMIFS(tblFinancials[Amount],tblFinancials[AccountName],$A8,tblFinancials[FullDate],">="&DATE(C$4,1,1),tblFinancials[FullDate],"<="&DATE(C$4,12,31)) -> 1527404 | D8: =SUMIFS(tblFinancials[Amount],tblFinancials[AccountName],$A8,tblFinancials[FullDate],">="&DATE(D$4,1,1),tblFinancials[FullDate],"<="&DATE(D$4,12,31)) -> 1194194.8 | E8: =IFERROR(C8/B8-1,0) -> 0.14627999 | F8: =IFERROR(D8/C8-1,0) -> -0.21815396
A9: Total Revenue | B9: =SUM(B6:B8) -> 4178883 | C9: =SUM(C6:C8) -> 4538318.6 | D9: =SUM(D6:D8) -> 4864066.1 | E9: =IFERROR(C9/B9-1,0) -> 0.086012365 | F9: =IFERROR(D9/C9-1,0) -> 0.071777124
A12: Cost of Goods Sold | B12: =SUMIFS(tblFinancials[Amount],tblFinancials[AccountName],$A12,tblFinancials[FullDate],">="&DATE(B$4,1,1),tblFinancials[FullDate],"<="&DATE(B$4,12,31)) -> -2444646.6 | C12: =SUMIFS(tblFinancials[Amount],tblFinancials[AccountName],$A12,tblFinancials[FullDate],">="&DATE(C$4,1,1),tblFinancials[FullDate],"<="&DATE(C$4,12,31)) -> -2654916.4 | D12: =SUMIFS(tblFinancials[Amount],tblFinancials[AccountName],$A12,tblFinancials[FullDate],">="&DATE(D$4,1,1),tblFinancials[FullDate],"<="&DATE(D$4,12,31)) -> -2845478.7
A13: Gross Profit | B13: =B9+B12 -> 1734236.4 | C13: =C9+C12 -> 1883402.2 | D13: =D9+D12 -> 2018587.4 | E13: =IFERROR(C13/B13-1,0) -> 0.08601236 | F13: =IFERROR(D13/C13-1,0) -> 0.071777122
A14: Gross Margin % | B14: =IFERROR(B13/B9,0) -> 0.415 | C14: =IFERROR(C13/C9,0) -> 0.415 | D14: =IFERROR(D13/D9,0) -> 0.415
A16: Operating Expenses
A17: Salaries Expense | B17: =SUMIFS(tblFinancials[Amount],tblFinancials[AccountName],$A17,tblFinancials[FullDate],">="&DATE(B$4,1,1),tblFinancials[FullDate],"<="&DATE(B$4,12,31)) -> -52242.94 | C17: =SUMIFS(tblFinancials[Amount],tblFinancials[AccountName],$A17,tblFinancials[FullDate],">="&DATE(C$4,1,1),tblFinancials[FullDate],"<="&DATE(C$4,12,31)) -> -96375.75 | D17: =SUMIFS(tblFinancials[Amount],tblFinancials[AccountName],$A17,tblFinancials[FullDate],">="&DATE(D$4,1,1),tblFinancials[FullDate],"<="&DATE(D$4,12,31)) -> -114708.77
A18: Payroll Taxes | B18: =SUMIFS(tblFinancials[Amount],tblFinancials[AccountName],$A18,tblFinancials[FullDate],">="&DATE(B$4,1,1),tblFinancials[FullDate],"<="&DATE(B$4,12,31)) -> -80037.57 | C18: =SUMIFS(tblFinancials[Amount],tblFinancials[AccountName],$A18,tblFinancials[FullDate],">="&DATE(C$4,1,1),tblFinancials[FullDate],"<="&DATE(C$4,12,31)) -> -69239.39 | D18: =SUMIFS(tblFinancials[Amount],tblFinancials[AccountName],$A18,tblFinancials[FullDate],">="&DATE(D$4,1,1),tblFinancials[FullDate],"<="&DATE(D$4,12,31)) -> -121548.56
A19: Employee Benefits | B19: =SUMIFS(tblFinancials[Amount],tblFinancials[AccountName],$A19,tblFinancials[FullDate],">="&DATE(B$4,1,1),tblFinancials[FullDate],"<="&DATE(B$4,12,31)) -> -151449.31 | C19: =SUMIFS(tblFinancials[Amount],tblFinancials[AccountName],$A19,tblFinancials[FullDate],">="&DATE(C$4,1,1),tblFinancials[FullDate],"<="&DATE(C$4,12,31)) -> -76396.41 | D19: =SUMIFS(tblFinancials[Amount],tblFinancials[AccountName],$A19,tblFinancials[FullDate],">="&DATE(D$4,1,1),tblFinancials[FullDate],"<="&DATE(D$4,12,31)) -> -127470.29
A20: Marketing Expense | B20: =SUMIFS(tblFinancials[Amount],tblFinancials[AccountName],$A20,tblFinancials[FullDate],">="&DATE(B$4,1,1),tblFinancials[FullDate],"<="&DATE(B$4,12,31)) -> -98516.96 | C20: =SUMIFS(tblFinancials[Amount],tblFinancials[AccountName],$A20,tblFinancials[FullDate],">="&DATE(C$4,1,1),tblFinancials[FullDate],"<="&DATE(C$4,12,31)) -> -117550.9 | D20: =SUMIFS(tblFinancials[Amount],tblFinancials[AccountName],$A20,tblFinancials[FullDate],">="&DATE(D$4,1,1),tblFinancials[FullDate],"<="&DATE(D$4,12,31)) -> -134698.59
A21: Software Expense | B21: =SUMIFS(tblFinancials[Amount],tblFinancials[AccountName],$A21,tblFinancials[FullDate],">="&DATE(B$4,1,1),tblFinancials[FullDate],"<="&DATE(B$4,12,31)) -> -75424.46 | C21: =SUMIFS(tblFinancials[Amount],tblFinancials[AccountName],$A21,tblFinancials[FullDate],">="&DATE(C$4,1,1),tblFinancials[FullDate],"<="&DATE(C$4,12,31)) -> -92312.64 | D21: =SUMIFS(tblFinancials[Amount],tblFinancials[AccountName],$A21,tblFinancials[FullDate],">="&DATE(D$4,1,1),tblFinancials[FullDate],"<="&DATE(D$4,12,31)) -> -95296.73
A22: Rent Expense | B22: =SUMIFS(tblFinancials[Amount],tblFinancials[AccountName],$A22,tblFinancials[FullDate],">="&DATE(B$4,1,1),tblFinancials[FullDate],"<="&DATE(B$4,12,31)) -> -88551.8 | C22: =SUMIFS(tblFinancials[Amount],tblFinancials[AccountName],$A22,tblFinancials[FullDate],">="&DATE(C$4,1,1),tblFinancials[FullDate],"<="&DATE(C$4,12,31)) -> -83485.21 | D22: =SUMIFS(tblFinancials[Amount],tblFinancials[AccountName],$A22,tblFinancials[FullDate],">="&DATE(D$4,1,1),tblFinancials[FullDate],"<="&DATE(D$4,12,31)) -> -40564.25
A23: Utilities Expense | B23: =SUMIFS(tblFinancials[Amount],tblFinancials[AccountName],$A23,tblFinancials[FullDate],">="&DATE(B$4,1,1),tblFinancials[FullDate],"<="&DATE(B$4,12,31)) -> -92702.17 | C23: =SUMIFS(tblFinancials[Amount],tblFinancials[AccountName],$A23,tblFinancials[FullDate],">="&DATE(C$4,1,1),tblFinancials[FullDate],"<="&DATE(C$4,12,31)) -> -148036.79 | D23: =SUMIFS(tblFinancials[Amount],tblFinancials[AccountName],$A23,tblFinancials[FullDate],">="&DATE(D$4,1,1),tblFinancials[FullDate],"<="&DATE(D$4,12,31)) -> -106019.65
A24: Insurance Expense | B24: =SUMIFS(tblFinancials[Amount],tblFinancials[AccountName],$A24,tblFinancials[FullDate],">="&DATE(B$4,1,1),tblFinancials[FullDate],"<="&DATE(B$4,12,31)) -> -73253.14 | C24: =SUMIFS(tblFinancials[Amount],tblFinancials[AccountName],$A24,tblFinancials[FullDate],">="&DATE(C$4,1,1),tblFinancials[FullDate],"<="&DATE(C$4,12,31)) -> -103891.91 | D24: =SUMIFS(tblFinancials[Amount],tblFinancials[AccountName],$A24,tblFinancials[FullDate],">="&DATE(D$4,1,1),tblFinancials[FullDate],"<="&DATE(D$4,12,31)) -> -70498.07
A25: Travel Expense | B25: =SUMIFS(tblFinancials[Amount],tblFinancials[AccountName],$A25,tblFinancials[FullDate],">="&DATE(B$4,1,1),tblFinancials[FullDate],"<="&DATE(B$4,12,31)) -> -93867.94 | C25: =SUMIFS(tblFinancials[Amount],tblFinancials[AccountName],$A25,tblFinancials[FullDate],">="&DATE(C$4,1,1),tblFinancials[FullDate],"<="&DATE(C$4,12,31)) -> -58534.91 | D25: =SUMIFS(tblFinancials[Amount],tblFinancials[AccountName],$A25,tblFinancials[FullDate],">="&DATE(D$4,1,1),tblFinancials[FullDate],"<="&DATE(D$4,12,31)) -> -110065.08
A26: Professional Services | B26: =SUMIFS(tblFinancials[Amount],tblFinancials[AccountName],$A26,tblFinancials[FullDate],">="&DATE(B$4,1,1),tblFinancials[FullDate],"<="&DATE(B$4,12,31)) -> -102318.47 | C26: =SUMIFS(tblFinancials[Amount],tblFinancials[AccountName],$A26,tblFinancials[FullDate],">="&DATE(C$4,1,1),tblFinancials[FullDate],"<="&DATE(C$4,12,31)) -> -120394.77 | D26: =SUMIFS(tblFinancials[Amount],tblFinancials[AccountName],$A26,tblFinancials[FullDate],">="&DATE(D$4,1,1),tblFinancials[FullDate],"<="&DATE(D$4,12,31)) -> -80636.72
A27: Total Operating Expenses | B27: =SUM(B17:B26) -> -908364.76 | C27: =SUM(C17:C26) -> -966218.68 | D27: =SUM(D17:D26) -> -1001506.7 | E27: =IFERROR(C27/B27-1,0) -> 0.063690185 | F27: =IFERROR(D27/C27-1,0) -> 0.036521784
A29: Operating Income | B29: =B13+B27 -> 825871.69 | C29: =C13+C27 -> 917183.54 | D29: =D13+D27 -> 1017080.7 | E29: =IFERROR(C29/B29-1,0) -> 0.11056421 | F29: =IFERROR(D29/C29-1,0) -> 0.10891731
A30: Operating Margin % | B30: =IFERROR(B29/B9,0) -> 0.19762977 | C30: =IFERROR(C29/C9,0) -> 0.20209765 | D30: =IFERROR(D29/D9,0) -> 0.20910092
A32: Income Tax Expense | B32: =SUMIFS(tblFinancials[Amount],tblFinancials[AccountName],$A32,tblFinancials[FullDate],">="&DATE(B$4,1,1),tblFinancials[FullDate],"<="&DATE(B$4,12,31)) -> -73672.76 | C32: =SUMIFS(tblFinancials[Amount],tblFinancials[AccountName],$A32,tblFinancials[FullDate],">="&DATE(C$4,1,1),tblFinancials[FullDate],"<="&DATE(C$4,12,31)) -> -100286.18 | D32: =SUMIFS(tblFinancials[Amount],tblFinancials[AccountName],$A32,tblFinancials[FullDate],">="&DATE(D$4,1,1),tblFinancials[FullDate],"<="&DATE(D$4,12,31)) -> -141548.81
A33: Net Income | B33: =B29+B32 -> 752198.93 | C33: =C29+C32 -> 816897.36 | D33: =D29+D32 -> 875531.89 | E33: =IFERROR(C33/B33-1,0) -> 0.086012393 | F33: =IFERROR(D33/C33-1,0) -> 0.071777108
A34: Net Profit Margin % | B34: =IFERROR(B33/B9,0) -> 0.18 | C34: =IFERROR(C33/C9,0) -> 0.18 | D34: =IFERROR(D33/D9,0) -> 0.18
A36: Historical Model Checks
A37: Revenue Check | B37: =IF(ROUND(B9,2)=ROUND(SUMIFS(tblFinancials[Amount],tblFinancials[FinancialStatement],"Income Statement",tblFinancials[AccountCategory],"Revenue",tblFinancials[FullDate],">="&DATE(B$4,1,1),tblFinancials[FullDate],"<="&DATE(B$4,12,31)),2),"OK","CHECK") -> OK | C37: =IF(ROUND(C9,2)=ROUND(SUMIFS(tblFinancials[Amount],tblFinancials[FinancialStatement],"Income Statement",tblFinancials[AccountCategory],"Revenue",tblFinancials[FullDate],">="&DATE(C$4,1,1),tblFinancials[FullDate],"<="&DATE(C$4,12,31)),2),"OK","CHECK") -> OK | D37: =IF(ROUND(D9,2)=ROUND(SUMIFS(tblFinancials[Amount],tblFinancials[FinancialStatement],"Income Statement",tblFinancials[AccountCategory],"Revenue",tblFinancials[FullDate],">="&DATE(D$4,1,1),tblFinancials[FullDate],"<="&DATE(D$4,12,31)),2),"OK","CHECK") -> OK
A38: Gross Profit Check | B38: =IF(ROUND(B13,2)=ROUND(B9+B12,2),"OK","CHECK") -> OK | C38: =IF(ROUND(C13,2)=ROUND(C9+C12,2),"OK","CHECK") -> OK | D38: =IF(ROUND(D13,2)=ROUND(D9+D12,2),"OK","CHECK") -> OK
A39: Operating Income Check | B39: =IF(ROUND(B29,2)=ROUND(B13+B27,2),"OK","CHECK") -> OK | C39: =IF(ROUND(C29,2)=ROUND(C13+C27,2),"OK","CHECK") -> OK | D39: =IF(ROUND(D29,2)=ROUND(D13+D27,2),"OK","CHECK") -> OK
A40: Net Income Check | B40: =IF(ROUND(B33,2)=ROUND(B29+B32,2),"OK","CHECK") -> OK | C40: =IF(ROUND(C33,2)=ROUND(C29+C32,2),"OK","CHECK") -> OK | D40: =IF(ROUND(D33,2)=ROUND(D29+D32,2),"OK","CHECK") -> OK

Sheet Historical Trends
A1: CASCADE OUTDOOR MANUFACTURING
A2: Historical Financial Trends
A4: Metric | B4: 2023 | C4: 2024 | D4: 2025
A5: Revenue | B5: ='Historical Actuals'!B9 -> 4178883 | C5: ='Historical Actuals'!C9 -> 4538318.6 | D5: ='Historical Actuals'!D9 -> 4864066.1
A6: Revenue Growth | C6: ='Historical Actuals'!E9 -> 0.086012365 | D6: ='Historical Actuals'!F9 -> 0.071777124
A7: Gross Profit | B7: ='Historical Actuals'!B13 -> 1734236.4 | C7: ='Historical Actuals'!C13 -> 1883402.2 | D7: ='Historical Actuals'!D13 -> 2018587.4
A8: Gross Margin | B8: ='Historical Actuals'!B14 -> 0.415 | C8: ='Historical Actuals'!C14 -> 0.415 | D8: ='Historical Actuals'!D14 -> 0.415
A9: Operating Expenses | B9: ='Historical Actuals'!B27 -> -908364.76 | C9: ='Historical Actuals'!C27 -> -966218.68 | D9: ='Historical Actuals'!D27 -> -1001506.7
A10: Operating Expense Growth | C10: =IFERROR(C9/B9-1,0) -> 0.063690185 | D10: =IFERROR(D9/C9-1,0) -> 0.036521784
A11: Operating Income | C11: ='Historical Actuals'!C29 -> 917183.54 | D11: ='Historical Actuals'!D29 -> 1017080.7
A12: Operating Margin | B12: ='Historical Actuals'!B30 -> 0.19762977 | C12: ='Historical Actuals'!C30 -> 0.20209765 | D12: ='Historical Actuals'!D30 -> 0.20910092
A13: Net Income | B13: ='Historical Actuals'!B33 -> 752198.93 | C13: ='Historical Actuals'!C33 -> 816897.36 | D13: ='Historical Actuals'!D33 -> 875531.89
A14: Net Profit Margin | B14: ='Historical Actuals'!B34 -> 0.18 | C14: ='Historical Actuals'!C34 -> 0.18 | D14: ='Historical Actuals'!D34 -> 0.18
A16: Revenue Mix
A17: Product Revenue | B17: =IFERROR('Historical Actuals'!B6/'Historical Actuals'!B9,0) -> 0.32513396 | C17: =IFERROR('Historical Actuals'!C6/'Historical Actuals'!C9,0) -> 0.33995338 | D17: =IFERROR('Historical Actuals'!D6/'Historical Actuals'!D9,0) -> 0.32769119
A18: Service Revenue | B18: =IFERROR('Historical Actuals'!B7/'Historical Actuals'!B9,0) -> 0.35600387 | C18: =IFERROR('Historical Actuals'!C7/'Historical Actuals'!C9,0) -> 0.32348937 | D18: =IFERROR('Historical Actuals'!D7/'Historical Actuals'!D9,0) -> 0.42679512
A19: Online Revenue | B19: =IFERROR('Historical Actuals'!B8/'Historical Actuals'!B9,0) -> 0.31886218 | C19: =IFERROR('Historical Actuals'!C8/'Historical Actuals'!C9,0) -> 0.33655725 | D19: =IFERROR('Historical Actuals'!D8/'Historical Actuals'!D9,0) -> 0.24551369
A21: Revenue Growth by Type
A22: Product Revenue Growth | C22: =IFERROR('Historical Actuals'!C6/'Historical Actuals'!B6-1,0) -> 0.13551221 | D22: =IFERROR('Historical Actuals'!D6/'Historical Actuals'!C6-1,0) -> 0.033117892
A23: Service Revenue Growth | C23: =IFERROR('Historical Actuals'!C7/'Historical Actuals'!B7-1,0) -> -0.013175169 | D23: =IFERROR('Historical Actuals'!D7/'Historical Actuals'!C7-1,0) -> 0.41404724
A24: Online Revenue Growth | C24: =IFERROR('Historical Actuals'!C8/'Historical Actuals'!B8-1,0) -> 0.14627999 | D24: =IFERROR('Historical Actuals'!D8/'Historical Actuals'!C8-1,0) -> -0.21815396
A27: Historical Management KPIs
A28: Revenue CAGR (2023–2025) | B28: =IFERROR(('Historical Actuals'!D9/'Historical Actuals'!B9)^(1/2)-1,0) -> 0.078871266
A29: Gross Margin Change | B29: ='Historical Actuals'!D14-'Historical Actuals'!B14 -> -2.7772899e-09
A30: Operating Margin Change | B30: ='Historical Actuals'!D30-'Historical Actuals'!B30 -> 0.011471151
A31: Net Margin Change | B31: ='Historical Actuals'!D34-'Historical Actuals'!B34 -> 1.9798045e-09

Sheet Revenue Analysis
A1: CASCADE OUTDOOR MANUFACTURING
A2: Historical Revenue Analysis
A4: Business Unit | B4: BusinessUnitKey | C4: 2023 | D4: 2024 | E4: 2025 | F4: 2024 YoY % | G4: 2025 YoY %
A5: Manufacturing | B5: 1 | C5: =SUMIFS(tblFinancials[Amount],tblFinancials[BusinessUnitKey],$B5,tblFinancials[AccountCategory],"Revenue",tblFinancials[FullDate],">="&DATE(C$4,1,1),tblFinancials[FullDate],"<="&DATE(C$4,12,31)) -> 912415.04 | D5: =SUMIFS(tblFinancials[Amount],tblFinancials[BusinessUnitKey],$B5,tblFinancials[AccountCategory],"Revenue",tblFinancials[FullDate],">="&DATE(D$4,1,1),tblFinancials[FullDate],"<="&DATE(D$4,12,31)) -> 967524.1 | E5: =SUMIFS(tblFinancials[Amount],tblFinancials[BusinessUnitKey],$B5,tblFinancials[AccountCategory],"Revenue",tblFinancials[FullDate],">="&DATE(E$4,1,1),tblFinancials[FullDate],"<="&DATE(E$4,12,31)) -> 1231127.4 | F5: =IFERROR(D5/C5-1,0) -> 0.060399114 | G5: =IFERROR(E5/D5-1,0) -> 0.27245138
A6: Wholesale | B6: 2 | C6: =SUMIFS(tblFinancials[Amount],tblFinancials[BusinessUnitKey],$B6,tblFinancials[AccountCategory],"Revenue",tblFinancials[FullDate],">="&DATE(C$4,1,1),tblFinancials[FullDate],"<="&DATE(C$4,12,31)) -> 963235.69 | D6: =SUMIFS(tblFinancials[Amount],tblFinancials[BusinessUnitKey],$B6,tblFinancials[AccountCategory],"Revenue",tblFinancials[FullDate],">="&DATE(D$4,1,1),tblFinancials[FullDate],"<="&DATE(D$4,12,31)) -> 1306632.9 | E6: =SUMIFS(tblFinancials[Amount],tblFinancials[BusinessUnitKey],$B6,tblFinancials[AccountCategory],"Revenue",tblFinancials[FullDate],">="&DATE(E$4,1,1),tblFinancials[FullDate],"<="&DATE(E$4,12,31)) -> 1181754.6 | F6: =IFERROR(D6/C6-1,0) -> 0.35650378 | G6: =IFERROR(E6/D6-1,0) -> -0.095572586
A7: Retail | B7: 3 | C7: =SUMIFS(tblFinancials[Amount],tblFinancials[BusinessUnitKey],$B7,tblFinancials[AccountCategory],"Revenue",tblFinancials[FullDate],">="&DATE(C$4,1,1),tblFinancials[FullDate],"<="&DATE(C$4,12,31)) -> 1174289.1 | D7: =SUMIFS(tblFinancials[Amount],tblFinancials[BusinessUnitKey],$B7,tblFinancials[AccountCategory],"Revenue",tblFinancials[FullDate],">="&DATE(D$4,1,1),tblFinancials[FullDate],"<="&DATE(D$4,12,31)) -> 1000351.3 | E7: =SUMIFS(tblFinancials[Amount],tblFinancials[BusinessUnitKey],$B7,tblFinancials[AccountCategory],"Revenue",tblFinancials[FullDate],">="&DATE(E$4,1,1),tblFinancials[FullDate],"<="&DATE(E$4,12,31)) -> 1420953.4 | F7: =IFERROR(D7/C7-1,0) -> -0.14812182 | G7: =IFERROR(E7/D7-1,0) -> 0.42045448
A8: E-Commerce | B8: 4 | C8: =SUMIFS(tblFinancials[Amount],tblFinancials[BusinessUnitKey],$B8,tblFinancials[AccountCategory],"Revenue",tblFinancials[FullDate],">="&DATE(C$4,1,1),tblFinancials[FullDate],"<="&DATE(C$4,12,31)) -> 1128943.2 | D8: =SUMIFS(tblFinancials[Amount],tblFinancials[BusinessUnitKey],$B8,tblFinancials[AccountCategory],"Revenue",tblFinancials[FullDate],">="&DATE(D$4,1,1),tblFinancials[FullDate],"<="&DATE(D$4,12,31)) -> 1263810.4 | E8: =SUMIFS(tblFinancials[Amount],tblFinancials[BusinessUnitKey],$B8,tblFinancials[AccountCategory],"Revenue",tblFinancials[FullDate],">="&DATE(E$4,1,1),tblFinancials[FullDate],"<="&DATE(E$4,12,31)) -> 1030230.7 | F8: =IFERROR(D8/C8-1,0) -> 0.11946326 | G8: =IFERROR(E8/D8-1,0) -> -0.18482179
A9: Total Revenue | C9: =SUM(C5:C8) -> 4178883 | D9: =SUM(D5:D8) -> 4538318.6 | E9: =SUM(E5:E8) -> 4864066.1 | F9: =IFERROR(D9/C9-1,0) -> 0.086012365 | G9: =IFERROR(E9/D9-1,0) -> 0.071777124
A12: Revenue by Region
A13: Region | B13: RegionKey | C13: 2023 | D13: 2024 | E13: 2025 | F13: 2024 YoY % | G13: 2025 YoY %
A14: West | B14: 1 | C14: =SUMIFS(tblFinancials[Amount],tblFinancials[RegionKey],$B14,tblFinancials[AccountCategory],"Revenue",tblFinancials[FullDate],">="&DATE(C$13,1,1),tblFinancials[FullDate],"<="&DATE(C$13,12,31)) -> 1171392.6 | D14: =SUMIFS(tblFinancials[Amount],tblFinancials[RegionKey],$B14,tblFinancials[AccountCategory],"Revenue",tblFinancials[FullDate],">="&DATE(D$13,1,1),tblFinancials[FullDate],"<="&DATE(D$13,12,31)) -> 1209083 | E14: =SUMIFS(tblFinancials[Amount],tblFinancials[RegionKey],$B14,tblFinancials[AccountCategory],"Revenue",tblFinancials[FullDate],">="&DATE(E$13,1,1),tblFinancials[FullDate],"<="&DATE(E$13,12,31)) -> 957037.82 | F14: =IFERROR(D14/C14-1,0) -> 0.032175693 | G14: =IFERROR(E14/D14-1,0) -> -0.20845978
A15: Midwest | B15: 2 | C15: =SUMIFS(tblFinancials[Amount],tblFinancials[RegionKey],$B15,tblFinancials[AccountCategory],"Revenue",tblFinancials[FullDate],">="&DATE(C$13,1,1),tblFinancials[FullDate],"<="&DATE(C$13,12,31)) -> 1022730.7 | D15: =SUMIFS(tblFinancials[Amount],tblFinancials[RegionKey],$B15,tblFinancials[AccountCategory],"Revenue",tblFinancials[FullDate],">="&DATE(D$13,1,1),tblFinancials[FullDate],"<="&DATE(D$13,12,31)) -> 1101158.3 | E15: =SUMIFS(tblFinancials[Amount],tblFinancials[RegionKey],$B15,tblFinancials[AccountCategory],"Revenue",tblFinancials[FullDate],">="&DATE(E$13,1,1),tblFinancials[FullDate],"<="&DATE(E$13,12,31)) -> 1202957.2 | F15: =IFERROR(D15/C15-1,0) -> 0.07668458 | G15: =IFERROR(E15/D15-1,0) -> 0.092447088
A16: South | B16: 3 | C16: =SUMIFS(tblFinancials[Amount],tblFinancials[RegionKey],$B16,tblFinancials[AccountCategory],"Revenue",tblFinancials[FullDate],">="&DATE(C$13,1,1),tblFinancials[FullDate],"<="&DATE(C$13,12,31)) -> 999109.27 | D16: =SUMIFS(tblFinancials[Amount],tblFinancials[RegionKey],$B16,tblFinancials[AccountCategory],"Revenue",tblFinancials[FullDate],">="&DATE(D$13,1,1),tblFinancials[FullDate],"<="&DATE(D$13,12,31)) -> 1249050.2 | E16: =SUMIFS(tblFinancials[Amount],tblFinancials[RegionKey],$B16,tblFinancials[AccountCategory],"Revenue",tblFinancials[FullDate],">="&DATE(E$13,1,1),tblFinancials[FullDate],"<="&DATE(E$13,12,31)) -> 1490814 | F16: =IFERROR(D16/C16-1,0) -> 0.25016371 | G16: =IFERROR(E16/D16-1,0) -> 0.19355818
A17: East | B17: 4 | C17: =SUMIFS(tblFinancials[Amount],tblFinancials[RegionKey],$B17,tblFinancials[AccountCategory],"Revenue",tblFinancials[FullDate],">="&DATE(C$13,1,1),tblFinancials[FullDate],"<="&DATE(C$13,12,31)) -> 985650.47 | D17: =SUMIFS(tblFinancials[Amount],tblFinancials[RegionKey],$B17,tblFinancials[AccountCategory],"Revenue",tblFinancials[FullDate],">="&DATE(D$13,1,1),tblFinancials[FullDate],"<="&DATE(D$13,12,31)) -> 979027.16 | E17: =SUMIFS(tblFinancials[Amount],tblFinancials[RegionKey],$B17,tblFinancials[AccountCategory],"Revenue",tblFinancials[FullDate],">="&DATE(E$13,1,1),tblFinancials[FullDate],"<="&DATE(E$13,12,31)) -> 1213257 | F17: =IFERROR(D17/C17-1,0) -> -0.006719735 | G17: =IFERROR(E17/D17-1,0) -> 0.23924758
A18: Total Revenue | C18: =SUM(C14:C17) -> 4178883 | D18: =SUM(D14:D17) -> 4538318.6 | E18: =SUM(E14:E17) -> 4864066.1 | F18: =IFERROR(D18/C18-1,0) -> 0.086012365 | G18: =IFERROR(E18/D18-1,0) -> 0.071777124

Sheet Expense Analysis
A1: CASCADE OUTDOOR MANUFACTURING
A2: Historical Operating Expense Analysis
A4: Department | B4: DepartmentKey | C4: 2023 | D4: 2024 | E4: 2025 | F4: 2024 YoY % | G4: 2025 YoY % | H4: 2025 Expense Mix
A5: Executive | B5: 1 | C5: =SUMIFS(tblFinancials[Amount],tblFinancials[DepartmentKey],$B5,tblFinancials[AccountCategory],"Operating Expense",tblFinancials[FullDate],">="&DATE(C$4,1,1),tblFinancials[FullDate],"<="&DATE(C$4,12,31)) -> -89157.2 | D5: =SUMIFS(tblFinancials[Amount],tblFinancials[DepartmentKey],$B5,tblFinancials[AccountCategory],"Operating Expense",tblFinancials[FullDate],">="&DATE(D$4,1,1),tblFinancials[FullDate],"<="&DATE(D$4,12,31)) -> -140491.59 | E5: =SUMIFS(tblFinancials[Amount],tblFinancials[DepartmentKey],$B5,tblFinancials[AccountCategory],"Operating Expense",tblFinancials[FullDate],">="&DATE(E$4,1,1),tblFinancials[FullDate],"<="&DATE(E$4,12,31)) -> -134456.64 | F5: =IFERROR(D5/C5-1,0) -> 0.57577391 | G5: =IFERROR(E5/D5-1,0) -> -0.042955952 | H5: =IFERROR(E5/E13,0) -> 0.13425436
A6: Finance | B6: 2 | C6: =SUMIFS(tblFinancials[Amount],tblFinancials[DepartmentKey],$B6,tblFinancials[AccountCategory],"Operating Expense",tblFinancials[FullDate],">="&DATE(C$4,1,1),tblFinancials[FullDate],"<="&DATE(C$4,12,31)) -> -63275.71 | D6: =SUMIFS(tblFinancials[Amount],tblFinancials[DepartmentKey],$B6,tblFinancials[AccountCategory],"Operating Expense",tblFinancials[FullDate],">="&DATE(D$4,1,1),tblFinancials[FullDate],"<="&DATE(D$4,12,31)) -> -75718.71 | E6: =SUMIFS(tblFinancials[Amount],tblFinancials[DepartmentKey],$B6,tblFinancials[AccountCategory],"Operating Expense",tblFinancials[FullDate],">="&DATE(E$4,1,1),tblFinancials[FullDate],"<="&DATE(E$4,12,31)) -> -109025.24 | F6: =IFERROR(D6/C6-1,0) -> 0.19664734 | G6: =IFERROR(E6/D6-1,0) -> 0.43987186 | H6: =IFERROR(E6/E13,0) -> 0.10886122
A7: Human Resources | B7: 3 | C7: =SUMIFS(tblFinancials[Amount],tblFinancials[DepartmentKey],$B7,tblFinancials[AccountCategory],"Operating Expense",tblFinancials[FullDate],">="&DATE(C$4,1,1),tblFinancials[FullDate],"<="&DATE(C$4,12,31)) -> -80840.44 | D7: =SUMIFS(tblFinancials[Amount],tblFinancials[DepartmentKey],$B7,tblFinancials[AccountCategory],"Operating Expense",tblFinancials[FullDate],">="&DATE(D$4,1,1),tblFinancials[FullDate],"<="&DATE(D$4,12,31)) -> -100158.82 | E7: =SUMIFS(tblFinancials[Amount],tblFinancials[DepartmentKey],$B7,tblFinancials[AccountCategory],"Operating Expense",tblFinancials[FullDate],">="&DATE(E$4,1,1),tblFinancials[FullDate],"<="&DATE(E$4,12,31)) -> -174194.12 | F7: =IFERROR(D7/C7-1,0) -> 0.23896926 | G7: =IFERROR(E7/D7-1,0) -> 0.73917904 | H7: =IFERROR(E7/E13,0) -> 0.17393205
A8: Sales | B8: 4 | C8: =SUMIFS(tblFinancials[Amount],tblFinancials[DepartmentKey],$B8,tblFinancials[AccountCategory],"Operating Expense",tblFinancials[FullDate],">="&DATE(C$4,1,1),tblFinancials[FullDate],"<="&DATE(C$4,12,31)) -> -125819.73 | D8: =SUMIFS(tblFinancials[Amount],tblFinancials[DepartmentKey],$B8,tblFinancials[AccountCategory],"Operating Expense",tblFinancials[FullDate],">="&DATE(D$4,1,1),tblFinancials[FullDate],"<="&DATE(D$4,12,31)) -> -123310.94 | E8: =SUMIFS(tblFinancials[Amount],tblFinancials[DepartmentKey],$B8,tblFinancials[AccountCategory],"Operating Expense",tblFinancials[FullDate],">="&DATE(E$4,1,1),tblFinancials[FullDate],"<="&DATE(E$4,12,31)) -> -151909.95 | F8: =IFERROR(D8/C8-1,0) -> -0.01993956 | G8: =IFERROR(E8/D8-1,0) -> 0.23192598 | H8: =IFERROR(E8/E13,0) -> 0.15168141
A9: Marketing | B9: 5 | C9: =SUMIFS(tblFinancials[Amount],tblFinancials[DepartmentKey],$B9,tblFinancials[AccountCategory],"Operating Expense",tblFinancials[FullDate],">="&DATE(C$4,1,1),tblFinancials[FullDate],"<="&DATE(C$4,12,31)) -> -109322.91 | D9: =SUMIFS(tblFinancials[Amount],tblFinancials[DepartmentKey],$B9,tblFinancials[AccountCategory],"Operating Expense",tblFinancials[FullDate],">="&DATE(D$4,1,1),tblFinancials[FullDate],"<="&DATE(D$4,12,31)) -> -108724.82 | E9: =SUMIFS(tblFinancials[Amount],tblFinancials[DepartmentKey],$B9,tblFinancials[AccountCategory],"Operating Expense",tblFinancials[FullDate],">="&DATE(E$4,1,1),tblFinancials[FullDate],"<="&DATE(E$4,12,31)) -> -81967.01 | F9: =IFERROR(D9/C9-1,0) -> -0.0054708569 | G9: =IFERROR(E9/D9-1,0) -> -0.24610581 | H9: =IFERROR(E9/E13,0) -> 0.081843695
A10: Operations | B10: 6 | C10: =SUMIFS(tblFinancials[Amount],tblFinancials[DepartmentKey],$B10,tblFinancials[AccountCategory],"Operating Expense",tblFinancials[FullDate],">="&DATE(C$4,1,1),tblFinancials[FullDate],"<="&DATE(C$4,12,31)) -> -157597.56 | D10: =SUMIFS(tblFinancials[Amount],tblFinancials[DepartmentKey],$B10,tblFinancials[AccountCategory],"Operating Expense",tblFinancials[FullDate],">="&DATE(D$4,1,1),tblFinancials[FullDate],"<="&DATE(D$4,12,31)) -> -146199.04 | E10: =SUMIFS(tblFinancials[Amount],tblFinancials[DepartmentKey],$B10,tblFinancials[AccountCategory],"Operating Expense",tblFinancials[FullDate],">="&DATE(E$4,1,1),tblFinancials[FullDate],"<="&DATE(E$4,12,31)) -> -113383.66 | F10: =IFERROR(D10/C10-1,0) -> -0.072326754 | G10: =IFERROR(E10/D10-1,0) -> -0.22445688 | H10: =IFERROR(E10/E13,0) -> 0.11321308
A11: Informaton Technology | B11: 7 | C11: =SUMIFS(tblFinancials[Amount],tblFinancials[DepartmentKey],$B11,tblFinancials[AccountCategory],"Operating Expense",tblFinancials[FullDate],">="&DATE(C$4,1,1),tblFinancials[FullDate],"<="&DATE(C$4,12,31)) -> -186606.9 | D11: =SUMIFS(tblFinancials[Amount],tblFinancials[DepartmentKey],$B11,tblFinancials[AccountCategory],"Operating Expense",tblFinancials[FullDate],">="&DATE(D$4,1,1),tblFinancials[FullDate],"<="&DATE(D$4,12,31)) -> -143596.91 | E11: =SUMIFS(tblFinancials[Amount],tblFinancials[DepartmentKey],$B11,tblFinancials[AccountCategory],"Operating Expense",tblFinancials[FullDate],">="&DATE(E$4,1,1),tblFinancials[FullDate],"<="&DATE(E$4,12,31)) -> -122610.08 | F11: =IFERROR(D11/C11-1,0) -> -0.23048446 | G11: =IFERROR(E11/D11-1,0) -> -0.14615099 | H11: =IFERROR(E11/E13,0) -> 0.12242562
A12: Customer Service | B12: 8 | C12: =SUMIFS(tblFinancials[Amount],tblFinancials[DepartmentKey],$B12,tblFinancials[AccountCategory],"Operating Expense",tblFinancials[FullDate],">="&DATE(C$4,1,1),tblFinancials[FullDate],"<="&DATE(C$4,12,31)) -> -95744.31 | D12: =SUMIFS(tblFinancials[Amount],tblFinancials[DepartmentKey],$B12,tblFinancials[AccountCategory],"Operating Expense",tblFinancials[FullDate],">="&DATE(D$4,1,1),tblFinancials[FullDate],"<="&DATE(D$4,12,31)) -> -128017.85 | E12: =SUMIFS(tblFinancials[Amount],tblFinancials[DepartmentKey],$B12,tblFinancials[AccountCategory],"Operating Expense",tblFinancials[FullDate],">="&DATE(E$4,1,1),tblFinancials[FullDate],"<="&DATE(E$4,12,31)) -> -113960.01 | F12: =IFERROR(D12/C12-1,0) -> 0.3370805 | G12: =IFERROR(E12/D12-1,0) -> -0.10981156 | H12: =IFERROR(E12/E13,0) -> 0.11378856
A13: Total Operating Expenses | C13: =SUM(C5:C12) -> -908364.76 | D13: =SUM(D5:D12) -> -966218.68 | E13: =SUM(E5:E12) -> -1001506.7 | H13: =SUM(H5:H12) -> 1

Sheet Monthly Analysis
A1: CASCADE OUTDOOR MANUFACTURING
A2: Historical Monthly Financial Analysis
A4: Month | B4: 2023 Revenue | C4: 2024 Revenue | D4: 2025 Revenue | E4: 2024 YoY % | F4: 2025 YoY % | G4: 2025 Revenue Mix | H4: Month Number | J4: Revenue Seasonality Summary
A5: January | B5: =SUMIFS(tblFinancials[Amount],tblFinancials[AccountCategory],"Revenue",tblFinancials[FullDate],">="&DATE(2023,$H5,1),tblFinancials[FullDate],"<"&EDATE(DATE(2023,$H5,1),1)) -> 304093.39 | C5: =SUMIFS(tblFinancials[Amount],tblFinancials[AccountCategory],"Revenue",tblFinancials[FullDate],">="&DATE(2024,$H5,1),tblFinancials[FullDate],"<"&EDATE(DATE(2024,$H5,1),1)) -> 331735.32 | D5: =SUMIFS(tblFinancials[Amount],tblFinancials[AccountCategory],"Revenue",tblFinancials[FullDate],">="&DATE(2025,$H5,1),tblFinancials[FullDate],"<"&EDATE(DATE(2025,$H5,1),1)) -> 353732.04 | E5: =IFERROR(C5/B5-1,0) -> 0.090899477 | F5: =IFERROR(D5/C5-1,0) -> 0.066308043 | G5: =IFERROR(D5/$D$17,0) -> 0.072723527 | H5: 1
A6: February | B6: =SUMIFS(tblFinancials[Amount],tblFinancials[AccountCategory],"Revenue",tblFinancials[FullDate],">="&DATE(2023,$H6,1),tblFinancials[FullDate],"<"&EDATE(DATE(2023,$H6,1),1)) -> 291128.88 | C6: =SUMIFS(tblFinancials[Amount],tblFinancials[AccountCategory],"Revenue",tblFinancials[FullDate],">="&DATE(2024,$H6,1),tblFinancials[FullDate],"<"&EDATE(DATE(2024,$H6,1),1)) -> 317057.67 | D6: =SUMIFS(tblFinancials[Amount],tblFinancials[AccountCategory],"Revenue",tblFinancials[FullDate],">="&DATE(2025,$H6,1),tblFinancials[FullDate],"<"&EDATE(DATE(2025,$H6,1),1)) -> 339053.14 | E6: =IFERROR(C6/B6-1,0) -> 0.089062926 | F6: =IFERROR(D6/C6-1,0) -> 0.06937372 | G6: =IFERROR(D6/$D$17,0) -> 0.069705702 | H6: 2 | J6: Month | K6: 2023 Mix | L6: 2024 Mix | M6: 2025 Mix | N6: 3-Year Average
A7: March | B7: =SUMIFS(tblFinancials[Amount],tblFinancials[AccountCategory],"Revenue",tblFinancials[FullDate],">="&DATE(2023,$H7,1),tblFinancials[FullDate],"<"&EDATE(DATE(2023,$H7,1),1)) -> 317411.6 | C7: =SUMIFS(tblFinancials[Amount],tblFinancials[AccountCategory],"Revenue",tblFinancials[FullDate],">="&DATE(2024,$H7,1),tblFinancials[FullDate],"<"&EDATE(DATE(2024,$H7,1),1)) -> 348594.04 | D7: =SUMIFS(tblFinancials[Amount],tblFinancials[AccountCategory],"Revenue",tblFinancials[FullDate],">="&DATE(2025,$H7,1),tblFinancials[FullDate],"<"&EDATE(DATE(2025,$H7,1),1)) -> 373615.06 | E7: =IFERROR(C7/B7-1,0) -> 0.098239762 | F7: =IFERROR(D7/C7-1,0) -> 0.071776959 | G7: =IFERROR(D7/$D$17,0) -> 0.076811263 | H7: 3 | J7: January | K7: =IFERROR(B5/$B$17,0) -> 0.07276906 | L7: =IFERROR(C5/$C$17,0) -> 0.073096525 | M7: =IFERROR(D5/$D$17,0) -> 0.072723527 | N7: =AVERAGE(K7:M7) -> 0.072863037
A8: April | B8: =SUMIFS(tblFinancials[Amount],tblFinancials[AccountCategory],"Revenue",tblFinancials[FullDate],">="&DATE(2023,$H8,1),tblFinancials[FullDate],"<"&EDATE(DATE(2023,$H8,1),1)) -> 340870.26 | C8: =SUMIFS(tblFinancials[Amount],tblFinancials[AccountCategory],"Revenue",tblFinancials[FullDate],">="&DATE(2024,$H8,1),tblFinancials[FullDate],"<"&EDATE(DATE(2024,$H8,1),1)) -> 377158.19 | D8: =SUMIFS(tblFinancials[Amount],tblFinancials[AccountCategory],"Revenue",tblFinancials[FullDate],">="&DATE(2025,$H8,1),tblFinancials[FullDate],"<"&EDATE(DATE(2025,$H8,1),1)) -> 398451.02 | E8: =IFERROR(C8/B8-1,0) -> 0.10645672 | F8: =IFERROR(D8/C8-1,0) -> 0.056455966 | G8: =IFERROR(D8/$D$17,0) -> 0.081917271 | H8: 4 | J8: February | K8: =IFERROR(B6/$B$17,0) -> 0.069666674 | L8: =IFERROR(C6/$C$17,0) -> 0.069862364 | M8: =IFERROR(D6/$D$17,0) -> 0.069705702 | N8: =AVERAGE(K8:M8) -> 0.069744913
A9: May | B9: 357855.3 | C9: =SUMIFS(tblFinancials[Amount],tblFinancials[AccountCategory],"Revenue",tblFinancials[FullDate],">="&DATE(2024,$H9,1),tblFinancials[FullDate],"<"&EDATE(DATE(2024,$H9,1),1)) -> 390508.44 | D9: =SUMIFS(tblFinancials[Amount],tblFinancials[AccountCategory],"Revenue",tblFinancials[FullDate],">="&DATE(2025,$H9,1),tblFinancials[FullDate],"<"&EDATE(DATE(2025,$H9,1),1)) -> 419822.65 | E9: =IFERROR(C9/B9-1,0) -> 0.091246769 | F9: =IFERROR(D9/C9-1,0) -> 0.075066777 | G9: =IFERROR(D9/$D$17,0) -> 0.08631105 | H9: 5 | J9: March | K9: =IFERROR(B7/$B$17,0) -> 0.075956086 | L9: =IFERROR(C7/$C$17,0) -> 0.076811275 | M9: =IFERROR(D7/$D$17,0) -> 0.076811263 | N9: =AVERAGE(K9:M9) -> 0.076526208
A10: June | B10: =SUMIFS(tblFinancials[Amount],tblFinancials[AccountCategory],"Revenue",tblFinancials[FullDate],">="&DATE(2023,$H10,1),tblFinancials[FullDate],"<"&EDATE(DATE(2023,$H10,1),1)) -> 372565.38 | C10: =SUMIFS(tblFinancials[Amount],tblFinancials[AccountCategory],"Revenue",tblFinancials[FullDate],">="&DATE(2024,$H10,1),tblFinancials[FullDate],"<"&EDATE(DATE(2024,$H10,1),1)) -> 402140.43 | D10: =SUMIFS(tblFinancials[Amount],tblFinancials[AccountCategory],"Revenue",tblFinancials[FullDate],">="&DATE(2025,$H10,1),tblFinancials[FullDate],"<"&EDATE(DATE(2025,$H10,1),1)) -> 426140.54 | E10: =IFERROR(C10/B10-1,0) -> 0.079382174 | F10: =IFERROR(D10/C10-1,0) -> 0.059680918 | G10: =IFERROR(D10/$D$17,0) -> 0.08760994 | H10: 6 | J10: April | K10: =IFERROR(B8/$B$17,0) -> 0.081569706 | L10: =IFERROR(C8/$C$17,0) -> 0.083105269 | M10: =IFERROR(D8/$D$17,0) -> 0.081917271 | N10: =AVERAGE(K10:M10) -> 0.082197415
A11: July | B11: =SUMIFS(tblFinancials[Amount],tblFinancials[AccountCategory],"Revenue",tblFinancials[FullDate],">="&DATE(2023,$H11,1),tblFinancials[FullDate],"<"&EDATE(DATE(2023,$H11,1),1)) -> 373124.78 | C11: =SUMIFS(tblFinancials[Amount],tblFinancials[AccountCategory],"Revenue",tblFinancials[FullDate],">="&DATE(2024,$H11,1),tblFinancials[FullDate],"<"&EDATE(DATE(2024,$H11,1),1)) -> 403427.72 | D11: =SUMIFS(tblFinancials[Amount],tblFinancials[AccountCategory],"Revenue",tblFinancials[FullDate],">="&DATE(2025,$H11,1),tblFinancials[FullDate],"<"&EDATE(DATE(2025,$H11,1),1)) -> 441078.15 | E11: =IFERROR(C11/B11-1,0) -> 0.081213957 | F11: =IFERROR(D11/C11-1,0) -> 0.093326334 | G11: =IFERROR(D11/$D$17,0) -> 0.090680953 | H11: 7 | J11: May | K11: =IFERROR(B9/$B$17,0) -> 0.085634199 | L11: =IFERROR(C9/$C$17,0) -> 0.086046942 | M11: =IFERROR(D9/$D$17,0) -> 0.08631105 | N11: =AVERAGE(K11:M11) -> 0.085997397
